<mujoco model="push joint">
  <compiler angle="radian" meshdir="assets" autolimits="true"/>

  <option integrator="implicitfast" impratio="10"/>

  <default>
    <default class="push">
      <material specular="0.5" shininess="0.25"/>
      <default class="push/visual">
        <geom type="cylinder" size="0.05 0.5" group="2" rgba="1 0 0 1"/>
      </default>
      <default class="push/collision">
        <geom type="cylinder" size="0.05 0.5" group="2" rgba="1 0 0 1"/>
      </default>
    </default>
  </default>

    <worldbody>
        <body name="push joint" pos="0 1 0" >
          <joint name="push_joint1"  type="hinge" axis="0 1 0" pos="0 1 0" />
          <freejoint/>
          <geom type="cylinder" size="0.05 0.5" group="2" rgba="1 0 0 1"/>
        </body>
    </worldbody>
</mujoco>